<?xml version="1.0" ?>
<!--
  Simple World for Kalman Filter Tutorial

  A flat ground plane with some visual markers to help observe robot motion.
-->
<sdf version="1.8">
  <world name="kalman_world">

    <!-- Physics -->
    <physics name="1ms" type="ignored">
      <max_step_size>0.001</max_step_size>
      <real_time_factor>1.0</real_time_factor>
    </physics>

    <!-- Plugins -->
    <plugin
      filename="gz-sim-physics-system"
      name="gz::sim::systems::Physics">
    </plugin>
    <plugin
      filename="gz-sim-user-commands-system"
      name="gz::sim::systems::UserCommands">
    </plugin>
    <plugin
      filename="gz-sim-scene-broadcaster-system"
      name="gz::sim::systems::SceneBroadcaster">
    </plugin>
    <plugin
      filename="gz-sim-sensors-system"
      name="gz::sim::systems::Sensors">
      <render_engine>ogre2</render_engine>
    </plugin>
    <plugin
      filename="gz-sim-imu-system"
      name="gz::sim::systems::Imu">
    </plugin>

    <!-- Lighting -->
    <light type="directional" name="sun">
      <cast_shadows>true</cast_shadows>
      <pose>0 0 10 0 0 0</pose>
      <diffuse>0.8 0.8 0.8 1</diffuse>
      <specular>0.2 0.2 0.2 1</specular>
      <attenuation>
        <range>1000</range>
        <constant>0.9</constant>
        <linear>0.01</linear>
        <quadratic>0.001</quadratic>
      </attenuation>
      <direction>-0.5 0.1 -0.9</direction>
    </light>

    <!-- Ground Plane -->
    <model name="ground_plane">
      <static>true</static>
      <link name="link">
        <collision name="collision">
          <geometry>
            <plane>
              <normal>0 0 1</normal>
              <size>100 100</size>
            </plane>
          </geometry>
        </collision>
        <visual name="visual">
          <geometry>
            <plane>
              <normal>0 0 1</normal>
              <size>100 100</size>
            </plane>
          </geometry>
          <material>
            <ambient>0.8 0.8 0.8 1</ambient>
            <diffuse>0.8 0.8 0.8 1</diffuse>
            <specular>0.2 0.2 0.2 1</specular>
          </material>
        </visual>
      </link>
    </model>

    <!-- Grid Lines for Visual Reference -->
    <!-- Origin marker -->
    <model name="origin_marker">
      <static>true</static>
      <pose>0 0 0.01 0 0 0</pose>
      <link name="link">
        <visual name="x_axis">
          <pose>0.5 0 0 0 0 0</pose>
          <geometry>
            <box>
              <size>1 0.02 0.02</size>
            </box>
          </geometry>
          <material>
            <ambient>1 0 0 1</ambient>
            <diffuse>1 0 0 1</diffuse>
          </material>
        </visual>
        <visual name="y_axis">
          <pose>0 0.5 0 0 0 0</pose>
          <geometry>
            <box>
              <size>0.02 1 0.02</size>
            </box>
          </geometry>
          <material>
            <ambient>0 1 0 1</ambient>
            <diffuse>0 1 0 1</diffuse>
          </material>
        </visual>
      </link>
    </model>

    <!-- Circle path marker (radius 2m) for robot to follow -->
    <model name="circle_path">
      <static>true</static>
      <pose>0 0 0.005 0 0 0</pose>
      <link name="link">
        <visual name="circle">
          <geometry>
            <cylinder>
              <radius>2.0</radius>
              <length>0.01</length>
            </cylinder>
          </geometry>
          <material>
            <ambient>0.3 0.3 0.8 0.3</ambient>
            <diffuse>0.3 0.3 0.8 0.3</diffuse>
          </material>
        </visual>
        <visual name="center">
          <geometry>
            <cylinder>
              <radius>0.05</radius>
              <length>0.02</length>
            </cylinder>
          </geometry>
          <material>
            <ambient>0.8 0.3 0.3 1</ambient>
            <diffuse>0.8 0.3 0.3 1</diffuse>
          </material>
        </visual>
      </link>
    </model>

    <!-- Simple Diff-Drive Robot -->
    <model name="robot">
      <pose>2 0 0.1 0 0 0</pose>

      <!-- Chassis -->
      <link name="chassis">
        <pose>0 0 0.05 0 0 0</pose>
        <inertial>
          <mass>5.0</mass>
          <inertia>
            <ixx>0.05</ixx>
            <iyy>0.1</iyy>
            <izz>0.1</izz>
          </inertia>
        </inertial>
        <collision name="collision">
          <geometry>
            <box>
              <size>0.3 0.2 0.1</size>
            </box>
          </geometry>
        </collision>
        <visual name="visual">
          <geometry>
            <box>
              <size>0.3 0.2 0.1</size>
            </box>
          </geometry>
          <material>
            <ambient>0.2 0.5 0.8 1</ambient>
            <diffuse>0.2 0.5 0.8 1</diffuse>
          </material>
        </visual>

        <!-- IMU Sensor -->
        <sensor name="imu_sensor" type="imu">
          <always_on>1</always_on>
          <update_rate>100</update_rate>
          <visualize>false</visualize>
          <topic>imu</topic>
          <imu>
            <angular_velocity>
              <x>
                <noise type="gaussian">
                  <mean>0.0</mean>
                  <stddev>0.01</stddev>
                </noise>
              </x>
              <y>
                <noise type="gaussian">
                  <mean>0.0</mean>
                  <stddev>0.01</stddev>
                </noise>
              </y>
              <z>
                <noise type="gaussian">
                  <mean>0.0</mean>
                  <stddev>0.01</stddev>
                </noise>
              </z>
            </angular_velocity>
            <linear_acceleration>
              <x>
                <noise type="gaussian">
                  <mean>0.0</mean>
                  <stddev>0.1</stddev>
                </noise>
              </x>
              <y>
                <noise type="gaussian">
                  <mean>0.0</mean>
                  <stddev>0.1</stddev>
                </noise>
              </y>
              <z>
                <noise type="gaussian">
                  <mean>0.0</mean>
                  <stddev>0.1</stddev>
                </noise>
              </z>
            </linear_acceleration>
          </imu>
        </sensor>
      </link>

      <!-- Left Wheel -->
      <link name="left_wheel">
        <pose>0 0.12 0.05 -1.5707 0 0</pose>
        <inertial>
          <mass>0.5</mass>
          <inertia>
            <ixx>0.001</ixx>
            <iyy>0.001</iyy>
            <izz>0.001</izz>
          </inertia>
        </inertial>
        <collision name="collision">
          <geometry>
            <cylinder>
              <radius>0.05</radius>
              <length>0.04</length>
            </cylinder>
          </geometry>
          <surface>
            <friction>
              <ode>
                <mu>1.0</mu>
                <mu2>1.0</mu2>
              </ode>
            </friction>
          </surface>
        </collision>
        <visual name="visual">
          <geometry>
            <cylinder>
              <radius>0.05</radius>
              <length>0.04</length>
            </cylinder>
          </geometry>
          <material>
            <ambient>0.2 0.2 0.2 1</ambient>
            <diffuse>0.2 0.2 0.2 1</diffuse>
          </material>
        </visual>
      </link>

      <!-- Right Wheel -->
      <link name="right_wheel">
        <pose>0 -0.12 0.05 -1.5707 0 0</pose>
        <inertial>
          <mass>0.5</mass>
          <inertia>
            <ixx>0.001</ixx>
            <iyy>0.001</iyy>
            <izz>0.001</izz>
          </inertia>
        </inertial>
        <collision name="collision">
          <geometry>
            <cylinder>
              <radius>0.05</radius>
              <length>0.04</length>
            </cylinder>
          </geometry>
          <surface>
            <friction>
              <ode>
                <mu>1.0</mu>
                <mu2>1.0</mu2>
              </ode>
            </friction>
          </surface>
        </collision>
        <visual name="visual">
          <geometry>
            <cylinder>
              <radius>0.05</radius>
              <length>0.04</length>
            </cylinder>
          </geometry>
          <material>
            <ambient>0.2 0.2 0.2 1</ambient>
            <diffuse>0.2 0.2 0.2 1</diffuse>
          </material>
        </visual>
      </link>

      <!-- Caster Wheel -->
      <link name="caster">
        <pose>-0.1 0 0.025 0 0 0</pose>
        <inertial>
          <mass>0.2</mass>
          <inertia>
            <ixx>0.0001</ixx>
            <iyy>0.0001</iyy>
            <izz>0.0001</izz>
          </inertia>
        </inertial>
        <collision name="collision">
          <geometry>
            <sphere>
              <radius>0.025</radius>
            </sphere>
          </geometry>
          <surface>
            <friction>
              <ode>
                <mu>0.01</mu>
                <mu2>0.01</mu2>
              </ode>
            </friction>
          </surface>
        </collision>
        <visual name="visual">
          <geometry>
            <sphere>
              <radius>0.025</radius>
            </sphere>
          </geometry>
          <material>
            <ambient>0.3 0.3 0.3 1</ambient>
            <diffuse>0.3 0.3 0.3 1</diffuse>
          </material>
        </visual>
      </link>

      <!-- Joints -->
      <joint name="left_wheel_joint" type="revolute">
        <parent>chassis</parent>
        <child>left_wheel</child>
        <axis>
          <xyz>0 0 1</xyz>
          <limit>
            <lower>-1.79769e+308</lower>
            <upper>1.79769e+308</upper>
          </limit>
        </axis>
      </joint>

      <joint name="right_wheel_joint" type="revolute">
        <parent>chassis</parent>
        <child>right_wheel</child>
        <axis>
          <xyz>0 0 1</xyz>
          <limit>
            <lower>-1.79769e+308</lower>
            <upper>1.79769e+308</upper>
          </limit>
        </axis>
      </joint>

      <joint name="caster_joint" type="ball">
        <parent>chassis</parent>
        <child>caster</child>
      </joint>

      <!-- Diff Drive Plugin -->
      <plugin
        filename="gz-sim-diff-drive-system"
        name="gz::sim::systems::DiffDrive">
        <left_joint>left_wheel_joint</left_joint>
        <right_joint>right_wheel_joint</right_joint>
        <wheel_separation>0.24</wheel_separation>
        <wheel_radius>0.05</wheel_radius>
        <odom_publish_frequency>10</odom_publish_frequency>
        <topic>cmd_vel</topic>
        <odom_topic>odom</odom_topic>
        <frame_id>odom</frame_id>
        <child_frame_id>base_link</child_frame_id>
      </plugin>

      <!-- Odometry Publisher Plugin (with noise for Kalman demo) -->
      <plugin
        filename="gz-sim-odometry-publisher-system"
        name="gz::sim::systems::OdometryPublisher">
        <odom_frame>odom</odom_frame>
        <robot_base_frame>base_link</robot_base_frame>
        <odom_publish_frequency>10</odom_publish_frequency>
        <odom_topic>odom_noisy</odom_topic>
        <gaussian_noise>0.05</gaussian_noise>
      </plugin>

    </model>

  </world>
</sdf>
